<?xml version='1.0'?>

<robot name="duckiebot" xmlns:xacro="http://www.ros.org/wiki/xacro">

  <xacro:property name="cameraSize" value="0.01"/>
  <xacro:property name="cameraMass" value="0.01"/>
  <xacro:property name="compuMass" value="0.01"/>

  <!-- Constants -->
  <xacro:property name="PI" value="3.1415926535897931"/>

  <!-- Chassis properties -->
  <xacro:property name="chassisHeight" value="0.0623"/>
  <xacro:property name="chassisLength" value="0.198"/>
  <xacro:property name="chassisWidth" value="0.119"/>
  <xacro:property name="chassisMass" value="0.15"/>

  <!-- Caster wheel properties -->
  <xacro:property name="casterRadius" value="0.021"/>
  <xacro:property name="casterMass" value="0.09"/>
  <xacro:property name="casterOffsetX" value="0.091"/>

  <!-- Differential-drive wheels properties -->
  <xacro:property name="wheelWidth" value="0.026"/>
  <xacro:property name="wheelRadius" value="0.032"/>
  <xacro:property name="wheelMass" value="0.05"/>
  <xacro:property name="wheelOffsetY" value="0.037"/>

  <xarco:include filename="deliberation/urdf/duckiebot.gazebo" />
  <xacro:include filename="deliberation/urdf/materials.xacro" />
  <xacro:include filename="deliberation/urdf/macros.xacro" />

  <pose>0 0 0 0 0 0</pose>

  <!-- base_link -->
  <link name='base_link'>
    <visual name='baseLinkVisual'>
      <origin xyz="0 0 0" rpy="0 0 0" />
      <geometry>
        <cylinder length="0" radius="0.0025" />
      </geometry>
      <material name="red" />
    </visual>  
  </link>

  <!-- Chassis -->
  <link name='chassis'>
    <collision name='collision'>
      <origin xyz="0 0 0" rpy=" 0 0 0"/>
      <geometry>
	      <!-- <mesh filename="package://home/jproque/dbros2_ws/src/deliberation/urdf/duckiebotFrame.dae"/> -->
        <mesh filename="package://deliberation/urdf/duckiebotFrame.dae"/>
      </geometry>
    </collision>
    <visual name='chassis_visual'>
      <origin xyz="0 0 0" rpy=" 0 0 0"/>
      <geometry>
	      <mesh filename="package://deliberation/urdf/duckiebotFrame.dae"/>
      </geometry>
      <material name="red" />
    </visual>
  </link>
  <joint type="fixed" name="base2Chassis">
    <child link="chassis" />
    <parent link="base_link" />
    <origin xyz="0 0 0.0325" />
  </joint>

  <!-- left_wheel -->
  <link name="aarrgrpi/left_wheel_axis">
    <origin xyz="0 0 0" rpy="0 0 0"/>
    <collision name="collision">
      <origin xyz="0 -0.07 0" rpy="0 0 0"/>
      <geometry>
	      <mesh filename="package://deliberation/urdf/duckiebot_leftwheel.dae"/>
      </geometry>
    </collision>
    <visual name="left_wheel_visual">
      <origin xyz="0 -0.07 0" rpy="0 0 0"/>
      <geometry>
	      <mesh filename="package://deliberation/urdf/duckiebot_leftwheel.dae"/>      
      </geometry>
      <material name="black"/>
    </visual>
  </link>
  <joint type="continuous" name="left_wheel_hinge">
    <origin xyz="0.0 0.07 0" rpy="0 0 0"/>
    <child link="aarrgrpi/left_wheel_axis"/>
    <parent link="chassis"/>
    <axis xyz="0 1 0" rpy="0 0 0"/>
    <limit effort="100" velocity="100"/>
    <joint_properties damping="0.0" friction="0.0"/>
  </joint>
  
  <!-- right_wheel -->
  <link name="aarrgrpi/right_wheel_axis">
    <origin xyz="0 0 0" rpy="0 0 0"/>
    <collision name="collision">
      <origin xyz="0 0.07 0" rpy="0 0 0"/>
      <geometry>
	      <mesh filename="package://deliberation/urdf/duckiebot_rightwheel.dae"/> 
      </geometry>
    </collision>
    <visual name="right_wheel_visual">
      <origin xyz="0 0.07 0" rpy="0 0 0"/>
      <geometry>
	      <mesh filename="package://deliberation/urdf/duckiebot_rightwheel.dae"/> 
      </geometry>
      <material name="black"/>
    </visual>
  </link>
  <joint type="continuous" name="right_wheel_hinge">
    <origin xyz="0.0 -0.07 0" rpy="0 0 0"/>
    <child link="aarrgrpi/right_wheel_axis"/>
    <parent link="chassis"/>
    <axis xyz="0 1 0" rpy="0 0 0"/>
    <limit effort="100" velocity="100"/>
    <joint_properties damping="0.0" friction="0.0"/>
  </joint>

  <!-- Computer -->
  <link name="computer">
    <collision>
      <origin xyz="0 0 0" rpy="0 0 0"/>
      <geometry>
	      <mesh filename="package://deliberation/urdf/duckiebot_computer.dae"/>
      </geometry>
    </collision>
    <visual name='comp_visual'>
      <origin xyz="0 0 0" rpy=" 0 0 0"/>
      <geometry>
	      <mesh filename="package://deliberation/urdf/duckiebot_computer.dae"/>
      </geometry>
      <material name="blue"/>
    </visual>
  </link>
  <joint name="computer_joint" type="fixed">
    <axis xyz="0 0 0" />
    <origin xyz="0 0 0" rpy="0 0 0"/>
    <parent link="chassis"/>
    <child link="computer"/>
  </joint>

  <!-- Camera sensor -->
  <link name="camera">
    <pose>0 0 0 0 0 0</pose>
    <collision>
      <origin xyz="-0.05 0 -0.055" rpy="0 -0.1 0"/>
      <geometry>
	      <mesh filename="package://deliberation/urdf/duckiebot_camera.dae"/>
      </geometry>
    </collision>
    <visual name='camvisual'>
      <origin xyz="-0.05 0 -0.055" rpy=" 0 -0.1 0"/>
      <geometry>
	      <mesh filename="package://deliberation/urdf/duckiebot_camera.dae"/>
      </geometry>
      <material name="black"/>
    </visual>
  </link>

  <!-- This joint info decides the pos of camera. Pitch(p in rpy) is angle to control orientation for duckiebot camera.After change values here, you need to change the pos info in collision part anf visual part just above.-->
  <joint name="camera_joint" type="fixed">
    <axis xyz="0 0 0" />
    <origin xyz="0.05 0 0.05" rpy="0 0.1 0"/> 
    <parent link="chassis"/>
    <child link="camera"/>
  </joint>

</robot>
